<mujoco model="arena">
  <compiler angle="degree" coordinate="local" inertiafromgeom="true"/>
  <option timestep="0.01" iterations="4" />
  <default>
    <joint armature="1" damping="1" limited="true"/>
    <geom contype="0" conaffinity="0" condim="3" density="5.0" friction="1 0.5 0.5" rgba="1.0 1.0 1.0 1"/>
  </default>
  <asset>
    <texture builtin="gradient" height="100" rgb1=".4 .5 .6" rgb2="0 0 0" type="skybox" width="100"/>
    <texture builtin="gradient" height="100" rgb1="1 0 0" rgb2="1 1 0" type="cube" width="100" name="tex_red"/>
    <texture builtin="gradient" height="100" rgb1="0.5 0 1" rgb2="0 0 1" type="cube" width="100" name="tex_blue"/>
    <texture builtin="checker" height="100" name="texplane" rgb1="0 0 0" rgb2="0.8 0.8 0.8" type="2d" width="100"/>
    <material name="m_arena" reflectance="0.5" shininess="1" specular="1" texrepeat="10 10" texture="texplane"/>
    <material name="m_red" texture="tex_red" texuniform="true"/>
    <material name="m_blue" texture="tex_blue" texuniform="true"/>
  </asset>
  <worldbody>
    <light cutoff="100" diffuse="1 1 1" dir="-0 0 -1.3" directional="true" exponent="1" pos="0 0 1.3" specular=".1 .1 .1"/>
    <geom conaffinity="4" contype="16" condim="3" material="m_arena" name="arena_floor" pos="0 0 -1.5" size="2.5 2.5 1.5" type="box" rgba="1 1 1 1"/>
    <camera name="free_cam" mode="track" pos="0 -8 8" xyaxes="1 0 0 0 0.7 0.7"/>
    <body name="red_the_red_one" pos="0 0 0">
      <camera name="red_track" mode="trackcom" pos="0 -4 4" xyaxes="1 0 0 0 0.7 0.7"/>
      <geom name="red_torso_geom" contype="1" conaffinity="16" pos="0 0 0" size="0.25" material="m_red" rgba=".8 .6 .4 1" type="sphere"/>
      <joint armature="0" damping="0" limited="false" margin="0.01" name="red_root" pos="0 0 0" type="free"/>
      <body name="red_front_left_leg" pos="0 0 0">
        <geom fromto="0.0 0.0 0.0 0.2 0.2 0.0" name="red_aux_1_geom" size="0.08" type="capsule" material="m_red" rgba=".8 .6 .4 1"/>
        <body name="red_aux_1" pos="0.2 0.2 0">
          <joint axis="0 0 1" name="red_hip_1" pos="0.0 0.0 0.0" range="-30 30" type="hinge"/>
          <geom fromto="0.0 0.0 0.0 0.2 0.2 0.0" conaffinity="16" name="red_left_leg_geom" size="0.08" type="capsule" material="m_red" rgba=".8 .6 .4 1"/>
          <body pos="0.2 0.2 0">
            <joint axis="-1 1 0" name="red_ankle_1" pos="0.0 0.0 0.0" range="30 70" type="hinge"/>
            <geom fromto="0.0 0.0 0.0 0.4 0.4 0.0" conaffinity="16" name="red_left_ankle_geom" size="0.08" type="capsule" material="m_red" rgba=".8 .6 .4 1"/>
            <geom name="red_left_foot_geom" contype="2" conaffinity="16" pos="0.4 0.4 0" size="0.08" type="sphere" mass="0" material="m_red" rgba=".8 .6 .4 1"/>
          </body>
        </body>
      </body>
      <body name="red_front_right_leg" pos="0 0 0">
        <geom fromto="0.0 0.0 0.0 -0.2 0.2 0.0" name="red_aux_2_geom" size="0.08" type="capsule" material="m_red" rgba=".8 .6 .4 1"/>
        <body name="red_aux_2" pos="-0.2 0.2 0">
          <joint axis="0 0 1" name="red_hip_2" pos="0.0 0.0 0.0" range="-30 30" type="hinge"/>
          <geom fromto="0.0 0.0 0.0 -0.2 0.2 0.0" conaffinity="16" name="red_right_leg_geom" size="0.08" type="capsule" material="m_red" rgba=".8 .6 .4 1"/>
          <body pos="-0.2 0.2 0">
            <joint axis="1 1 0" name="red_ankle_2" pos="0.0 0.0 0.0" range="-70 -30" type="hinge"/>
            <geom fromto="0.0 0.0 0.0 -0.4 0.4 0.0" conaffinity="16" name="red_right_ankle_geom" size="0.08" type="capsule" material="m_red" rgba=".8 .6 .4 1"/>
            <geom name="red_right_foot_geom" contype="2" conaffinity="16" pos="-0.4 0.4 0" size="0.08" type="sphere" mass="0" material="m_red" rgba=".8 .6 .4 1"/>
          </body>
        </body>
      </body>
      <body name="red_back_leg" pos="0 0 0">
        <geom fromto="0.0 0.0 0.0 -0.2 -0.2 0.0" name="red_aux_3_geom" size="0.08" type="capsule" material="m_red" rgba=".8 .6 .4 1"/>
        <body name="red_aux_3" pos="-0.2 -0.2 0">
          <joint axis="0 0 1" name="red_hip_3" pos="0.0 0.0 0.0" range="-30 30" type="hinge"/>
          <geom fromto="0.0 0.0 0.0 -0.2 -0.2 0.0" conaffinity="16" name="red_back_leg_geom" size="0.08" type="capsule" material="m_red" rgba=".8 .6 .4 1"/>
          <body pos="-0.2 -0.2 0">
            <joint axis="-1 1 0" name="red_ankle_3" pos="0.0 0.0 0.0" range="-70 -30" type="hinge"/>
            <geom fromto="0.0 0.0 0.0 -0.4 -0.4 0.0" conaffinity="16" name="red_third_ankle_geom" size="0.08" type="capsule" material="m_red" rgba=".8 .6 .4 1"/>
            <geom name="red_third_foot_geom" contype="2" conaffinity="16" pos="-0.4 -0.4 0" size="0.08" type="sphere" mass="0" material="m_red" rgba=".8 .6 .4 1"/>
          </body>
        </body>
      </body>
      <body name="red_right_back_leg" pos="0 0 0">
        <geom fromto="0.0 0.0 0.0 0.2 -0.2 0.0" name="red_aux_4_geom" size="0.08" type="capsule" material="m_red" rgba=".8 .6 .4 1"/>
        <body name="red_aux_4" pos="0.2 -0.2 0">
          <joint axis="0 0 1" name="red_hip_4" pos="0.0 0.0 0.0" range="-30 30" type="hinge"/>
          <geom fromto="0.0 0.0 0.0 0.2 -0.2 0.0" conaffinity="16" name="red_rightback_leg_geom" size="0.08" type="capsule" material="m_red" rgba=".8 .6 .4 1"/>
          <body pos="0.2 -0.2 0">
            <joint axis="1 1 0" name="red_ankle_4" pos="0.0 0.0 0.0" range="30 70" type="hinge"/>
            <geom fromto="0.0 0.0 0.0 0.4 -0.4 0.0" conaffinity="16" name="red_fourth_ankle_geom" size="0.08" type="capsule" material="m_red" rgba=".8 .6 .4 1"/>
            <geom name="red_fourth_foot_geom" contype="2" conaffinity="16" pos="0.4 -0.4 0" size="0.08" type="sphere" mass="0" material="m_red" rgba=".8 .6 .4 1"/>
          </body>
        </body>
      </body>
    </body>

  </worldbody>
  <actuator>
    <motor ctrllimited="true" ctrlrange="-1.0 1.0" joint="red_hip_4" gear="450"/>
    <motor ctrllimited="true" ctrlrange="-1.0 1.0" joint="red_ankle_4" gear="450"/>
    <motor ctrllimited="true" ctrlrange="-1.0 1.0" joint="red_hip_1" gear="450"/>
    <motor ctrllimited="true" ctrlrange="-1.0 1.0" joint="red_ankle_1" gear="450"/>
    <motor ctrllimited="true" ctrlrange="-1.0 1.0" joint="red_hip_2" gear="450"/>
    <motor ctrllimited="true" ctrlrange="-1.0 1.0" joint="red_ankle_2" gear="450"/>
    <motor ctrllimited="true" ctrlrange="-1.0 1.0" joint="red_hip_3" gear="450"/>
    <motor ctrllimited="true" ctrlrange="-1.0 1.0" joint="red_ankle_3" gear="450"/>
    
  </actuator>
</mujoco>